<?xml version="1.0"?>
<robot xmlns:xacro="http://www.ros.org/wiki/xacro" name="sensor_axis_m5013">
  <xacro:property name="ptz_joint_effort_limit" value="100.0"/>
  <xacro:property name="ptz_joint_velocity_limit" value="100.0"/>
  <xacro:property name="ptz_joint_friction" value="0.1"/>
  <xacro:property name="ptz_joint_damping" value="0.1"/>
  <xacro:property name="ptz_mechanical_reduction" value="1.0"/>
  <xacro:macro name="sensor_axis_m5013" params="name parent *origin">
    <joint name="${name}_joint" type="fixed">
      <axis xyz="0 1 0"/>
      <!--
	      <origin xyz="0.180 0.0 0.270"/>
-->
      <xacro:insert_block name="origin"/>
      <parent link="${parent}"/>
      <child link="${name}_link"/>
    </joint>
    <link name="${name}_link">
      <inertial>
        <origin xyz="0 0 0" rpy="0 0 0"/>
        <mass value="0.1"/>
        <origin xyz="0 0 0" rpy="0 0 0"/>
        <inertia ixx="0.1" ixy="0" ixz="0" iyy="0.1" iyz="0" izz="0.1"/>
      </inertial>
      <visual>
        <origin xyz="0 0 0" rpy="0 ${M_PI/2} 0"/>
        <!-- to center the axis model -->
        <material name="axis_color">
          <color rgba="0.1 0.1 0.1 1"/>
        </material>
        <geometry>
          <mesh filename="package://robotnik_sensors/meshes/axis_m5013.dae" scale="1.0 1.0 1.0"/>
        </geometry>
      </visual>
      <collision>
        <origin xyz="0.0 0.0 0" rpy="0 ${M_PI/2} 0"/>
        <geometry>
          <mesh filename="package://robotnik_sensors/meshes/axis_m5013.stl" scale="1.0 1.0 1.0"/>
        </geometry>
      </collision>
    </link>
    <joint name="joint_${name}_pan" type="revolute">
      <axis xyz="0 0 -1"/>
      <origin xyz="0.04 0.0 0.0" rpy="0 0 0"/>
      <!-- check the displacement -->
      <parent link="${name}_link"/>
      <child link="${name}_pan_link"/>
      <limit effort="${ptz_joint_effort_limit}" velocity="${ptz_joint_velocity_limit}" lower="-3.1416" upper="3.1416"/>
      <joint_properties damping="${ptz_joint_damping}" friction="{ptz_joint_friction}"/>
    </joint>
    <link name="${name}_pan_link">
      <inertial>
        <mass value="0.1"/>
        <origin xyz="0 0 0" rpy="0 0 0"/>
        <inertia ixx="0.1" ixy="0" ixz="0" iyy="0.1" iyz="0" izz="0.1"/>
      </inertial>
    </link>
    <transmission name="${name}_pan_trans">
      <type>transmission_interface/SimpleTransmission</type>
      <joint name="joint_${name}_pan">
        <hardwareInterface>PositionJointInterface</hardwareInterface>
      </joint>
      <actuator name="pan_motor">
        <hardwareInterface>PositionJointInterface</hardwareInterface>
        <mechanicalReduction>${ptz_mechanical_reduction}</mechanicalReduction>
      </actuator>
    </transmission>
    <joint name="joint_${name}_tilt" type="revolute">
      <axis xyz="0 -1 0"/>
      <origin xyz="0.0 0.0 0.0"/>
      <parent link="${name}_pan_link"/>
      <child link="${name}_tilt_link"/>
      <limit effort="${ptz_joint_effort_limit}" velocity="${ptz_joint_velocity_limit}" lower="-1.5708" upper="1.5708"/>
      <joint_properties damping="${ptz_joint_damping}" friction="{ptz_joint_friction}"/>
    </joint>
    <link name="${name}_tilt_link">
      <inertial>
        <mass value="0.1"/>
        <origin xyz="0 0 0" rpy="0 0 0"/>
        <inertia ixx="0.1" ixy="0" ixz="0" iyy="0.1" iyz="0" izz="0.1"/>
      </inertial>
    </link>
    <transmission name="${name}_tilt_trans">
      <type>transmission_interface/SimpleTransmission</type>
      <joint name="joint_${name}_tilt">
        <hardwareInterface>PositionJointInterface</hardwareInterface>
      </joint>
      <actuator name="tilt_motor">
        <hardwareInterface>PositionJointInterface</hardwareInterface>
        <mechanicalReduction>${ptz_mechanical_reduction}</mechanicalReduction>
      </actuator>
    </transmission>
    <joint name="${name}_frame_joint" type="fixed">
      <origin xyz="0 0 0" rpy="0 0 0"/>
      <parent link="${name}_tilt_link"/>
      <child link="${name}_frame"/>
    </joint>
    <link name="${name}_frame">
      <inertial>
        <mass value="0.001"/>
        <origin xyz="0 0 0"/>
        <inertia ixx="0.0001" ixy="0.0" ixz="0.0" iyy="0.0001" iyz="0.0" izz="0.0001"/>
      </inertial>
    </link>
    <!-- Optical frame -->
    <joint name="${name}_optical_joint" type="fixed">
      <origin xyz="0 0 0" rpy="${-M_PI/2} 0 ${-M_PI/2}"/>
      <parent link="${name}_frame"/>
      <child link="${name}_optical_frame"/>
    </joint>
    <link name="${name}_optical_frame">
      <inertial>
        <mass value="0.001"/>
        <origin xyz="0 0 0"/>
        <inertia ixx="0.0001" ixy="0.0" ixz="0.0" iyy="0.0001" iyz="0.0" izz="0.0001"/>
      </inertial>
    </link>
    <gazebo reference="${name}_link">
      <material>Gazebo/FlatBlack</material>
    </gazebo>

    <!-- Axis sensor for simulation -->
    <sensor_axis_m5013_gazebo/>

  </xacro:macro>


	<xacro:macro name="sensor_axis_m5013_gazebo">

		<gazebo reference="${name}_frame"> <!-- the image will be generated from this (${name}_frame) point of view, with the front being the X axis -->
			<sensor type="camera" name="${name}_sensor">
				<update_rate>30.0</update_rate>
				<camera name="${name}">
					<horizontal_fov>${60.0*M_PI/180.0}</horizontal_fov>
					<image>
						<format>R8G8B8</format>
						<width>640</width>
						<height>480</height>
					</image>
					<clip>
						<near>0.05</near>
						<far>8.0</far>
					</clip>
				</camera>
				<plugin name="${name}_controller" filename="libgazebo_ros_camera.so">
				    <cameraName>${name}</cameraName>
					<alwaysOn>true</alwaysOn>
					<updateRate>0.0</updateRate>
					<cameraName>${name}</cameraName>
					<imageTopicName>image_raw</imageTopicName>
					<cameraInfoTopicName>camera_info</cameraInfoTopicName>
					<frameName>${name}_optical_frame</frameName>
					<!-- this is just which name the Image msg will have, it does not affect the simulation.
					     However must be set to the optical_frame,  -->
					<hackBaseline>0.07</hackBaseline>
					<distortionK1>0.0</distortionK1>
					<distortionK2>0.0</distortionK2>
					<distortionK3>0.0</distortionK3>
					<distortionT1>0.0</distortionT1>
					<distortionT2>0.0</distortionT2>
				</plugin>
			</sensor>
		</gazebo>

	</xacro:macro>

</robot>
