<?xml version="1.0"?>
<robot xmlns:xacro="http://wiki.ros.org/xacro" name="sensor_link_750_nh">
  <xacro:property name="ptz_joint_effort_limit" value="1.0"/>
  <xacro:property name="ptz_joint_velocity_limit" value="1.0"/>
  <xacro:property name="ptz_joint_friction" value="0.1"/>
  <xacro:property name="ptz_joint_damping" value="0.1"/>
  <xacro:property name="ptz_mechanical_reduction" value="1.0"/>  
  <xacro:property name="PI" value="3.14159265359"/>

  <xacro:macro name="sensor_link_750_nh" params="prefix parent *origin far:=^|8.0 near:=^|0.05 prefix_topic:=^ptz_camera">
    
    <joint name="${prefix}_joint" type="fixed">
      <axis xyz="0 1 0"/>
      <xacro:insert_block name="origin"/>
      <parent link="${parent}"/>
      <child link="${prefix}_base_link"/>
    </joint>
    <link name="${prefix}_base_link">
      <inertial>
        <origin xyz="0.066 0 0" rpy="0 0 0"/>
        <mass value="0.8"/>
        <xacro:solid_cuboid_inertia m="0.8" w="0.165" h="0.165" d="0.132" />
      </inertial>
      <visual>
        <origin xyz="-0.07 -0.07 -0.045" rpy="0 0 0"/>
        <material name="grey_color">
          <color rgba="0.1 0.1 0.1 1"/>
        </material>
        <geometry>
          <mesh filename="package://robotnik_sensors/meshes/link_750_base.stl" scale="0.001 0.001 0.001"/>
        </geometry>
      </visual>
      <collision>
        <origin xyz="-0.07 -0.07 -0.045" rpy="0 0 0"/>
        <geometry>
          <mesh filename="package://robotnik_sensors/meshes/link_750_base.stl" scale="0.001 0.001 0.001"/>
        </geometry>
      </collision>
    </link>

    <joint name="${prefix}_pan_joint" type="revolute">
      <axis xyz="0 0 -1"/>
      <origin xyz="0.0 0.0 0.0318" rpy="0 0 0"/>
      <!-- check the displacement -->
      <parent link="${prefix}_base_link"/>
      <child link="${prefix}_pan_link"/>
      <limit effort="${ptz_joint_effort_limit}" velocity="${ptz_joint_velocity_limit}" lower="-3.1416" upper="3.1416"/>
      <joint_properties damping="${ptz_joint_damping}" friction="{ptz_joint_friction}"/>
    </joint>
    <link name="${prefix}_pan_link">
      <inertial>
        <mass value="0.1"/>
        <origin xyz="0 0 0" rpy="0 0 0"/>
        <xacro:solid_cuboid_inertia m="0.1" w="0.1" h="0.11" d="0.11" />
      </inertial>
      <visual>
        <origin xyz="0 0 0" rpy="0 0 0"/>
        <material name="grey_color">
          <color rgba="0.1 0.1 0.1 1"/>
        </material>
        <geometry>
          <mesh filename="package://robotnik_sensors/meshes/link_750_pan.stl" scale="1.0 1.0 1.0"/>
        </geometry>
      </visual>
      <collision>
        <origin xyz="0.0 0.0 0" rpy="0 0 0"/>
        <geometry>
          <mesh filename="package://robotnik_sensors/meshes/link_750_pan.stl" scale="1.0 1.0 1.0"/>
        </geometry>
      </collision>
    </link>
    <transmission name="${prefix}_pan_trans">
      <type>transmission_interface/SimpleTransmission</type>
      <joint name="${prefix}_pan_joint">
        <hardwareInterface>hardware_interface/PositionJointInterface</hardwareInterface>
      </joint>
      <actuator name="${prefix}pan_motor">
        <hardwareInterface>hardware_interface/PositionJointInterface</hardwareInterface>
        <mechanicalReduction>${ptz_mechanical_reduction}</mechanicalReduction>
      </actuator>
    </transmission>

    <joint name="${prefix}_tilt_joint" type="revolute">
      <axis xyz="0 -1 0"/>
      <origin xyz="0.0 0.0 0.102" rpy="0 0 0"/>
      <parent link="${prefix}_pan_link"/>
      <child link="${prefix}_tilt_link"/>
      <limit effort="${ptz_joint_effort_limit}" velocity="${ptz_joint_velocity_limit}" lower="-1.5708" upper="1.5708"/>
      <joint_properties damping="${ptz_joint_damping}" friction="{ptz_joint_friction}"/>
    </joint>
    <link name="${prefix}_tilt_link">
      <inertial>
        <mass value="0.1"/>
        <origin xyz="0 0 0" rpy="0 0 0"/>
        <xacro:solid_cuboid_inertia m="0.1" w="0.11" h="0.11" d="0.1" />
      </inertial>
      <visual>
        <origin xyz="0 0 0" rpy="0 0 0"/>
        <material name="grey_color">
          <color rgba="0.1 0.1 0.1 1"/>
        </material>
        <geometry>
          <mesh filename="package://robotnik_sensors/meshes/link_750_tilt.stl" scale="1.0 1.0 1.0"/>
        </geometry>
      </visual>
      <collision>
        <origin xyz="0.0 0.0 0" rpy="0 0 0"/>
        <geometry>
          <mesh filename="package://robotnik_sensors/meshes/link_750_tilt.stl" scale="1.0 1.0 1.0"/>
        </geometry>
      </collision>
    </link>
    <transmission name="${prefix}_tilt_trans">
      <type>transmission_interface/SimpleTransmission</type>
      <joint name="${prefix}_tilt_joint">
        <hardwareInterface>hardware_interface/PositionJointInterface</hardwareInterface>
      </joint>
      <actuator name="${prefix}tilt_motor">
        <hardwareInterface>hardware_interface/PositionJointInterface</hardwareInterface>
        <mechanicalReduction>${ptz_mechanical_reduction}</mechanicalReduction>
      </actuator>
    </transmission>

    <joint name="${prefix}_frame_joint" type="fixed">
      <origin xyz="0 0 0" rpy="0 0 0"/>
      <parent link="${prefix}_tilt_link"/>
      <child link="${prefix}_frame_link"/>
    </joint>
    <link name="${prefix}_frame_link">
      <inertial>
        <mass value="0.1"/>
        <origin xyz="0 0 0"/>
        <xacro:solid_cuboid_inertia m="0.1" w="0.11" h="0.11" d="0.1" />
      </inertial>
    </link>
    <!-- Optical frame -->
    <joint name="${prefix}_optical_joint" type="fixed">
      <origin xyz="0.02 0 0" rpy="0 0 0"/>
      <parent link="${prefix}_frame_link"/>
      <child link="${prefix}_optical_frame_link"/>
    </joint>
    <link name="${prefix}_optical_frame_link">
      <inertial>
        <mass value="0.1"/>
        <origin xyz="0 0 0"/>
        <xacro:solid_cuboid_inertia m="0.1" w="0.11" h="0.11" d="0.1" />
      </inertial>
    </link>
    <gazebo reference="${prefix}_base_link">
      <material>Gazebo/DarkGrey</material>
    </gazebo>

    <!-- Axis sensor for simulation -->
    <xacro:sensor_link_750_nh_gazebo/>

  </xacro:macro>


  <xacro:macro name="sensor_link_750_nh_gazebo">

    <gazebo reference="${prefix}_optical_frame_link"> <!-- the image will be generated from this (${name}_frame) point of view, with the front being the X axis -->
      <sensor type="camera" name="${prefix}_sensor">
        <update_rate>30.0</update_rate>
        <camera name="${prefix_topic}">
          <horizontal_fov>${60.0*M_PI/180.0}</horizontal_fov>
          <image>
            <format>R8G8B8</format>
            <width>640</width>
            <height>480</height>
          </image>
          <clip>
            <near>${near}</near>
            <far>${far}</far>
          </clip>
        </camera>
        <plugin name="${prefix}_controller" filename="libgazebo_ros_camera.so">
          <alwaysOn>true</alwaysOn>
          <updateRate>0.0</updateRate>
          <cameraName>top_rgb_${prefix_topic}</cameraName>
          <imageTopicName>image_raw</imageTopicName>
          <cameraInfoTopicName>camera_info</cameraInfoTopicName>
          <frameName>${prefix}_optical_frame_link</frameName>
          <!-- this is just which name the Image msg will have, it does not affect the simulation.
               However must be set to the optical_frame,  -->
          <hackBaseline>0.07</hackBaseline>
          <distortionK1>0.0</distortionK1>
          <distortionK2>0.0</distortionK2>
          <distortionK3>0.0</distortionK3>
          <distortionT1>0.0</distortionT1>
          <distortionT2>0.0</distortionT2>
          <ignoreTfPrefix>1</ignoreTfPrefix>
        </plugin>
      </sensor>
      <sensor type="camera" name="thermal_${prefix}_sensor">
        <update_rate>30.0</update_rate>
        <camera>
          <horizontal_fov>${60.0*M_PI/180.0}</horizontal_fov>
          <image>
            <format>R8G8B8</format>
            <width>640</width>
            <height>480</height>
          </image>
          <clip>
            <near>${near}</near>
            <far>${far}</far>
          </clip>
        </camera>
        
        <plugin name="thermal_camera_controller" filename="libgazebo_ros_thermal_camera.so">
          <alwaysOn>true</alwaysOn>
          <updateRate>10</updateRate>
          <cameraName>top_thermal_${prefix_topic}</cameraName>
          <imageTopicName>image_raw</imageTopicName>
          <cameraInfoTopicName>camera_info</cameraInfoTopicName>
          <frameName>${prefix}_optical_frame_link</frameName>
        </plugin>
      </sensor>
    </gazebo>

  </xacro:macro>

</robot>
